<?xml version="1.0" encoding="utf-8"?>
<!-- This URDF was automatically created by SolidWorks to URDF Exporter! Originally created by Stephen Brawner (brawner@gmail.com) 
     Commit Version: 1.6.0-4-g7f85cfe  Build Version: 1.6.7995.38578
     For more information, please see http://wiki.ros.org/sw_urdf_exporter -->
<robot
  name="DeltatWinURDF">
  <link
    name="base_link">
    <inertial>
      <origin
        xyz="-0.0952036209787758 7.78125513600558E-11 0.00197473007512181"
        rpy="0 0 0" />
      <mass
        value="0.296981329335048" />
      <inertia
        ixx="0.00806559842793603"
        ixy="-9.41934501552741E-14"
        ixz="5.49054252463097E-10"
        iyy="0.00147659261617276"
        iyz="-2.12387797879751E-09"
        izz="0.00928812511950579" />
    </inertial>
    <visual>
      <origin
        xyz="0 0 0"
        rpy="0 0 0" />
      <geometry>
        <mesh
          filename="package://DeltatWinURDF/meshes/base_link.STL" />
      </geometry>
      <material
        name="">
        <color
          rgba="0.968627450980392 0.87843137254902 0.6 1" />
      </material>
    </visual>
    <collision>
      <origin
        xyz="0 0 0"
        rpy="0 0 0" />
      <geometry>
        <mesh
          filename="package://DeltatWinURDF/meshes/base_link.STL" />
      </geometry>
    </collision>
  </link>
  <link
    name="right_motor">
    <inertial>
      <origin
        xyz="-1.0218294876907E-08 -6.00144618685593E-09 0.00181141041634729"
        rpy="0 0 0" />
      <mass
        value="0.00359973592304301" />
      <inertia
        ixx="9.02360838417436E-08"
        ixy="1.17837997236154E-07"
        ixz="-1.90562919430233E-14"
        iyy="9.42212831802528E-06"
        iyz="-1.21143734797756E-13"
        izz="9.47988709060552E-06" />
    </inertial>
    <visual>
      <origin
        xyz="0 0 0"
        rpy="0 0 0" />
      <geometry>
        <mesh
          filename="package://DeltatWinURDF/meshes/right_motor.STL" />
      </geometry>
      <material
        name="">
        <color
          rgba="0.0980392156862745 0.0980392156862745 0.0980392156862745 1" />
      </material>
    </visual>
    <collision>
      <origin
        xyz="0 0 0"
        rpy="0 0 0" />
      <geometry>
        <mesh
          filename="package://DeltatWinURDF/meshes/right_motor.STL" />
      </geometry>
    </collision>
  </link>
  <joint
    name="right_motor_joint"
    type="revolute">
    <origin
      xyz="-0.013011 0.25 0"
      rpy="1.5708 0 1.5708" />
    <parent
      link="base_link" />
    <child
      link="right_motor" />
    <axis
      xyz="0 0 1" />
    <limit
      lower="0"
      upper="0"
      effort="0"
      velocity="0" />
  </joint>
  <link
    name="left_motor">
    <inertial>
      <origin
        xyz="-4.73083400231999E-09 -1.5982328578194E-08 0.00181295979349896"
        rpy="0 0 0" />
      <mass
        value="0.0035962732627869" />
      <inertia
        ixx="9.01777971251138E-08"
        ixy="-1.17015369968996E-07"
        ixz="4.72219526573555E-14"
        iyy="9.40216890545166E-06"
        iyz="-8.94212671917933E-14"
        izz="9.45986253030714E-06" />
    </inertial>
    <visual>
      <origin
        xyz="0 0 0"
        rpy="0 0 0" />
      <geometry>
        <mesh
          filename="package://DeltatWinURDF/meshes/left_motor.STL" />
      </geometry>
      <material
        name="">
        <color
          rgba="0.0980392156862745 0.0980392156862745 0.0980392156862745 1" />
      </material>
    </visual>
    <collision>
      <origin
        xyz="0 0 0"
        rpy="0 0 0" />
      <geometry>
        <mesh
          filename="package://DeltatWinURDF/meshes/left_motor.STL" />
      </geometry>
    </collision>
  </link>
  <joint
    name="left_motor_joint"
    type="revolute">
    <origin
      xyz="-0.013 -0.25 0"
      rpy="1.5708 0 1.5708" />
    <parent
      link="base_link" />
    <child
      link="left_motor" />
    <axis
      xyz="0 0 1" />
    <limit
      lower="0"
      upper="0"
      effort="0"
      velocity="0" />
  </joint>
  <link
    name="right_elevon">
    <inertial>
      <origin
        xyz="-0.0206295101987303 0.180271196118253 0.00114188761501559"
        rpy="0 0 0" />
      <mass
        value="0.00429914039301486" />
      <inertia
        ixx="5.174539257616E-05"
        ixy="8.39192922141699E-07"
        ixz="5.15080918137687E-08"
        iyy="8.59467191797982E-07"
        iyz="8.49222569650825E-10"
        izz="5.2552381577933E-05" />
    </inertial>
    <visual>
      <origin
        xyz="0 0 0"
        rpy="0 0 0" />
      <geometry>
        <mesh
          filename="package://DeltatWinURDF/meshes/right_elevon.STL" />
      </geometry>
      <material
        name="">
        <color
          rgba="0.988235294117647 0.737254901960784 0.517647058823529 1" />
      </material>
    </visual>
    <collision>
      <origin
        xyz="0 0 0"
        rpy="0 0 0" />
      <geometry>
        <mesh
          filename="package://DeltatWinURDF/meshes/right_elevon.STL" />
      </geometry>
    </collision>
  </link>
  <joint
    name="right_elevon_joint"
    type="revolute">
    <origin
      xyz="-0.14351 0.068516 0"
      rpy="0 0 -0.17453" />
    <parent
      link="base_link" />
    <child
      link="right_elevon" />
    <axis
      xyz="0.016485 -0.99986 0" />
    <limit
      lower="-1.571"
      upper="1.571"
      effort="0"
      velocity="0" />
  </joint>
  <link
    name="left_elevon">
    <inertial>
      <origin
        xyz="-0.0196636403404296 -0.175581705344098 -0.00564668601966695"
        rpy="0 0 0" />
      <mass
        value="0.00429914039301486" />
      <inertia
        ixx="5.18235158616008E-05"
        ixy="-8.40480953883799E-07"
        ixz="-2.41892335100736E-07"
        iyy="8.59488427793871E-07"
        iyz="3.9881195973088E-09"
        izz="5.24742370564963E-05" />
    </inertial>
    <visual>
      <origin
        xyz="0 0 0"
        rpy="0 0 0" />
      <geometry>
        <mesh
          filename="package://DeltatWinURDF/meshes/left_elevon.STL" />
      </geometry>
      <material
        name="">
        <color
          rgba="0.988235294117647 0.737254901960784 0.517647058823529 1" />
      </material>
    </visual>
    <collision>
      <origin
        xyz="0 0 0"
        rpy="0 0 0" />
      <geometry>
        <mesh
          filename="package://DeltatWinURDF/meshes/left_elevon.STL" />
      </geometry>
    </collision>
  </link>
  <joint
    name="left_elevon_joint"
    type="revolute">
    <origin
      xyz="-0.14277 -0.073162 0"
      rpy="0 0 0.17453" />
    <parent
      link="base_link" />
    <child
      link="left_elevon" />
    <axis
      xyz="-0.016485 -0.99986 0" />
    <limit
      lower="-1.571"
      upper="1.571"
      effort="0"
      velocity="0" />
  </joint>
</robot>